<mujoco model="GEN3-6DOF_VISION_URDF_ARM_V01">
    <compiler angle="radian" />
    <size njmax="500" nconmax="100" />
    <asset>
        <mesh name="base_link" file="../meshes/base_link.STL" />
        <mesh name="shoulder_link" file="../meshes/shoulder_link.STL" />
        <mesh name="bicep_link" file="../meshes/bicep_link.STL" />
        <mesh name="forearm_link" file="../meshes/forearm_link.STL" />
        <mesh name="spherical_wrist_1_link" file="../meshes/spherical_wrist_1_link.STL" />
        <mesh name="spherical_wrist_2_link" file="../meshes/spherical_wrist_2_link.STL" />
        <mesh name="bracelet_with_vision_link" file="../meshes/bracelet_with_vision_link.STL" />
        <mesh name="robotiq_arg2f_base_link" file="robotiq_arg2f_85_base_link.stl" scale="0.001 0.001 0.001"/>
        <mesh name="robotiq_arg2f_85_outer_knuckle" file="robotiq_arg2f_85_outer_knuckle.stl" scale="0.001 0.001 0.001" />
        <mesh name="robotiq_arg2f_85_outer_finger" file="robotiq_arg2f_85_outer_finger.stl" scale="0.001 0.001 0.001" />
        <mesh name="robotiq_arg2f_85_inner_finger" file="robotiq_arg2f_85_inner_finger.stl" scale="0.001 0.001 0.001" />
        <mesh name="robotiq_arg2f_85_inner_knuckle" file="robotiq_arg2f_85_inner_knuckle.stl" scale="0.001 0.001 0.001" />
    </asset>
    <worldbody>
        <geom type="mesh" rgba="0.75294 0.75294 0.75294 1" mesh="base_link" />
        <body name="Shoulder_Link" pos="0 0 0.15643" quat="-3.67321e-06 -1 0 0">
            <inertial pos="-2.3e-05 -0.010364 -0.07336" quat="0.707051 0.0451246 -0.0453544 0.704263" mass="1.377" diaginertia="0.00488868 0.00457 0.00135132" />
            <joint name="Actuator1" pos="0 0 0" axis="0 0 1" damping="3" frictionloss="5.5" />
            <geom type="mesh" rgba="0.75294 0.75294 0.75294 1" mesh="shoulder_link" />
            <body name="Bicep_Link" pos="0 0.005375 -0.12838" quat="0.707105 0.707108 0 0">
                <inertial pos="3.5e-05 -0.208207 -0.01889" quat="0.499531 0.50049 -0.500566 0.499411" mass="1.262" diaginertia="0.0471882 0.046752 0.000849791" />
                <joint name="Actuator2" pos="0 0 0" axis="0 0 1" limited="true" range="-2.41 2.41" damping="3" frictionloss="5.5" />
                <geom type="mesh" rgba="0.75294 0.75294 0.75294 1" mesh="bicep_link" />
                <body name="ForeArm_Link" pos="0 -0.41 0" quat="-3.67321e-06 1 0 0">
                    <inertial pos="1.8e-05 0.076168 -0.01397" quat="0.513497 0.485985 -0.486188 0.513577" mass="0.93" diaginertia="0.00848774 0.008292 0.000604256" />
                    <joint name="Actuator3" pos="0 0 0" axis="0 0 1" limited="true" range="-2.66 2.66" damping="3" frictionloss="5.5"/>
                    <geom type="mesh" rgba="0.75294 0.75294 0.75294 1" mesh="forearm_link" />
                    <body name="SphericalWrist1_Link" pos="0 0.20843 -0.006375" quat="0.707105 0.707108 0 0">
                        <inertial pos="-1e-06 0.008486 -0.062937" quat="0.704382 -0.062019 0.062019 0.704382" mass="0.6781" diaginertia="0.00170753 0.001645 0.000347472" />
                        <joint name="Actuator4" pos="0 0 0" axis="0 0 1" damping="3" frictionloss="5.5"/>
                        <geom type="mesh" rgba="0.75294 0.75294 0.75294 1" mesh="spherical_wrist_1_link" />
                        <body name="SphericalWrist2_Link" pos="0 -0.00017505 -0.10593" quat="0.707105 -0.707108 0 0">
                            <inertial pos="-1e-06 0.046429 -0.008704" quat="0.5446 0.451011 -0.451011 0.5446" mass="0.678" diaginertia="0.00174437 0.001685 0.000351632" />
                            <joint name="Actuator5" pos="0 0 0" axis="0 0 1" limited="true" range="-2.23 2.23" damping="3" frictionloss="5.5"/>
                            <geom type="mesh" rgba="0.75294 0.75294 0.75294 1" mesh="spherical_wrist_2_link" />
                            <body name="Bracelet_Link" pos="0 0.10593 -0.00017505" quat="0.707105 0.707108 0 0">
                                <inertial pos="0.000281 0.011402 -0.029798" quat="0.394358 0.596779 -0.577293 0.393789" mass="0.5" diaginertia="0.000657336 0.000587019 0.000320645" />
                                <joint name="Actuator6" pos="0 0 0" axis="0 0 1" damping="3" frictionloss="5.5"/>
                                <geom type="mesh" rgba="0.75294 0.75294 0.75294 1" mesh="bracelet_with_vision_link" />
                                
                                <geom pos="0 0 -0.061525" quat="0 0.706825 0.707388 0" type="mesh" rgba="0.1 0.1 0.1 1" mesh="robotiq_arg2f_base_link" />
                                <body name="left_outer_knuckle" pos="-0.0306011 -2.43685e-05 -0.116429" quat="0 0.707388 -0.706825 0">
                                    <inertial pos="0.000163875 0.0554825 -0.0100755" quat="0.920541 0.390623 -0.00362953 0.00231744" mass="0.0311462" diaginertia="5.11372e-05 4.89464e-05 4.95906e-06" />
                                    <joint name="finger_joint" pos="0 0 0" axis="1 0 0" limited="true" range="0 0.8" damping="1.0" frictionloss="0.1"/>
                                    <geom type="mesh" rgba="0.792157 0.819608 0.933333 1" mesh="robotiq_arg2f_85_outer_knuckle" quat="0.707107 -0.707107 0 0"/>
                                    <geom pos="0 0.0315 -0.0041" type="mesh" rgba="0.1 0.1 0.1 1" mesh="robotiq_arg2f_85_outer_finger" contype="0" conaffinity="0"/>
                                    <body name="left_inner_finger" pos="0 0.0376 0.043">
                                        <inertial pos="0.000199506 0.0032692 0.00175282" quat="0.933621 0.35825 -0.00273441 0.00104851" mass="0.0156391" diaginertia="1.57977e-05 1.51089e-05 1.4647e-06" />
                                        <joint name="left_inner_finger_joint" pos="0 0 0" axis="1 0 0" limited="true" range="-0.8757 0.8757" />
                                        <geom type="mesh" rgba="0.1 0.1 0.1 1" mesh="robotiq_arg2f_85_inner_finger" contype="0" conaffinity="0"/>
                                        <geom size="0.011 0.003175 0.01875" 
                                            pos="0 -0.0220203 0.03242" 
                                            type="box" 
                                            rgba="0.9 0.9 0.9 1" 
                                            friction="2.0 0.5 0.01" 
                                            solimp="0.95 0.99 0.01" 
                                            solref="0.01 1" 
                                            condim="6" 
                                            margin="0.0001"/>
                                    </body>
                                </body>
                                <body name="left_inner_knuckle" pos="-0.0127 -1.01133e-05 -0.122945" quat="0 0.707388 -0.706825 0">
                                    <inertial pos="0.000123012 0.0507851 0.00103969" quat="0.497203 0.502496 -0.507943 0.492221" mass="0.0271177" diaginertia="2.83809e-05 2.61936e-05 2.81319e-06" />
                                    <joint name="left_inner_knuckle_joint" pos="0 0 0" axis="1 0 0" limited="true" range="0 0.8757" damping="1.5" frictionloss="0.2" />
                                    <geom type="mesh" rgba="0.1 0.1 0.1 1" mesh="robotiq_arg2f_85_inner_knuckle" contype="0" conaffinity="0"/>
                                </body>

                                <body name="right_outer_knuckle" pos="0.0306011 2.43685e-05 -0.116429" quat="0 0.706825 0.707388 0">
                                    <inertial pos="0.000163875 0.0554825 -0.0100755" quat="0.920541 0.390623 -0.00362953 0.00231744" mass="0.0311462" diaginertia="5.11372e-05 4.89464e-05 4.95906e-06" />
                                    <joint name="right_outer_knuckle_joint" pos="0 0 0" axis="1 0 0" limited="true" range="0 0.81" />
                                    <geom type="mesh" rgba="0.792157 0.819608 0.933333 1" mesh="robotiq_arg2f_85_outer_knuckle" quat="0.707107 -0.707107 0 0"/>
                                    <geom pos="0 0.0315 -0.0041" type="mesh" rgba="0.1 0.1 0.1 1" mesh="robotiq_arg2f_85_outer_finger" contype="0" conaffinity="0"/>
                                    <body name="right_inner_finger" pos="0 0.0376 0.043">
                                        <inertial pos="0.000199506 0.0032692 0.00175282" quat="0.933621 0.35825 -0.00273441 0.00104851" mass="0.0156391" diaginertia="1.57977e-05 1.51089e-05 1.4647e-06" />
                                        <joint name="right_inner_finger_joint" pos="0 0 0" axis="1 0 0" limited="true" range="-0.8757 0.8757" />
                                        <geom type="mesh" rgba="0.1 0.1 0.1 1" mesh="robotiq_arg2f_85_inner_finger" contype="0" conaffinity="0"/>
                                        <geom size="0.011 0.003175 0.01875" 
                                        pos="0 -0.0220203 0.03242" 
                                        type="box" 
                                        rgba="0.9 0.9 0.9 1" 
                                        friction="2.0 0.5 0.01" 
                                        solimp="0.95 0.99 0.01" 
                                        solref="0.01 1" 
                                        condim="6" 
                                        margin="0.0001"/>
                                    </body>
                                </body>

                                <body name="right_inner_knuckle" pos="0.0127 1.01133e-05 -0.122945" quat="0 0.706825 0.707388 0">
                                    <inertial pos="0.000123012 0.0507851 0.00103969" quat="0.497203 0.502496 -0.507943 0.492221" mass="0.0271177" diaginertia="2.83809e-05 2.61936e-05 2.81319e-06" />
                                    <joint name="right_inner_knuckle_joint" pos="0 0 0" axis="1 0 0" limited="true" range="0 0.8757" damping="1.5" frictionloss="0.2" />
                                    <geom type="mesh" rgba="0.1 0.1 0.1 1" mesh="robotiq_arg2f_85_inner_knuckle" contype="0" conaffinity="0" />
                                </body>

                            </body>
                        </body>
                    </body>
                </body>
            </body>
        </body>
    </worldbody>


     <contact>
        <exclude body1="Bracelet_Link" body2="left_outer_knuckle"/>
        <exclude body1="Bracelet_Link" body2="right_outer_knuckle"/>
        <exclude body1="Bracelet_Link" body2="left_inner_knuckle"/>
        <exclude body1="Bracelet_Link" body2="right_inner_knuckle"/>

        <exclude body1="left_inner_finger" body2="right_inner_finger"/>
        <exclude body1="left_inner_knuckle" body2="left_inner_finger"/>
        <exclude body1="right_inner_knuckle" body2="right_inner_finger"/>
        <exclude body1="left_outer_knuckle" body2="left_inner_finger"/>
        <exclude body1="right_outer_knuckle" body2="right_inner_finger"/>
    </contact>

    <equality>
        <joint joint1="right_outer_knuckle_joint" joint2="finger_joint" polycoef="0 1 0 0 0" solref="0.002 1" solimp="0.995 0.999 0.0001"/>
        <joint joint1="left_inner_knuckle_joint" joint2="finger_joint" polycoef="0 1 0 0 0" solref="0.002 1" solimp="0.995 0.999 0.0001"/>
        <joint joint1="right_inner_knuckle_joint" joint2="finger_joint" polycoef="0 1 0 0 0" solref="0.002 1" solimp="0.995 0.999 0.0001"/>
        <joint joint1="left_inner_finger_joint" joint2="finger_joint" polycoef="0 -1 0 0 0" solref="0.002 1" solimp="0.995 0.999 0.0001"/>
        <joint joint1="right_inner_finger_joint" joint2="finger_joint" polycoef="0 -1 0 0 0" solref="0.002 1" solimp="0.995 0.999 0.0001"/>
    </equality>

    <actuator>    
        <position name="Actuator1" joint="Actuator1" />
        <position name="Actuator2" joint="Actuator2" />
        <position name="Actuator3" joint="Actuator3" />
        <position name="Actuator4" joint="Actuator4" />
        <position name="Actuator5" joint="Actuator5" />
        <position name="Actuator6" joint="Actuator6" />        

        <position name="finger_joint" joint="finger_joint"/>    
    </actuator>
</mujoco>
