<mujoco model="kinova_field">
	<option noslip_iterations="70" />
	<size njmax="8000" nconmax="4000"/>
	<option timestep="0.001"/>
	
	<include file="GEN3-6DOF_VISION_URDF_ARM_V01.xml"/>	
	<asset>
		<texture name="floor_tex" type="2d" builtin="checker" rgb1=".2 .3 .4" rgb2=".1 .2 .3" width="100" height="100" />
		<material name="floor_material" texture="floor_tex" texuniform="true" />
		<texture name="wood_tex" type="2d" builtin="checker" rgb1="0.6 0.4 0.2" rgb2="0.5 0.3 0.15" width="10" height="10" />
		<material name="wood_material" texture="wood_tex" texuniform="true" />
	</asset>
	<visual>
        <map force = 0.1/>
    </visual>	
    
	<default>
        <default class ="viz">
            <geom contype="0" conaffinity="0" group="1" type="mesh" rgba=".6 .6 .7 1" />
        </default>
        <default class="cls">
            <geom group="2" rgba="0.79216 0.81961 0.93333 0.5"/>
        </default>
    </default>		

	<worldbody>
		<geom name="ground" type="plane" size="5 5 1" pos="0 0 -0.4"  material="floor_material" condim="6"/>

		<light directional="false" diffuse=".8 .8 .8" specular="0.3 0.3 0.3" pos="1 1 3" dir="-1 -1 -3"/>
		<light directional="false" diffuse=".8 .8 .8" specular="0.3 0.3 0.3" pos="1 -1 3" dir="-1 1 -3"/>
		<light directional="false" diffuse=".8 .8 .8" specular="0.3 0.3 0.3" pos="-1 0 3" dir="1 0 -3"/>

		<!-- 1. Robot Base Table -->
		<body name="table_robot" pos="0.0 0.0 -0.2">
			<geom name="table_robot_geom" type="box" size="0.2 0.2 0.2" material="wood_material" />
		 </body>

		<!-- 2. Small Source Table (For Box Only) -->
		<body name="table_source" pos="0.4 0.0 -0.2">
			<geom name="table_source_geom" type="box" size="0.1 0.1 0.2" material="wood_material" friction="1 0.5 0.01" />
		</body>

		<!-- 3. Target Table (Destination) -->
		<body name="table_target" pos="-0.5 0.0 -0.2">
			<geom name="table_target_geom" type="box" size="0.2 0.2 0.2" material="wood_material" friction="1 0.5 0.01" />
		</body>

		<body name="target_box" pos="0.4 0.0 0.025">
			<joint name="target_box_x" type="slide" axis="1 0 0" pos="0 0 0"/>
			<joint name="target_box_y" type="slide" axis="0 1 0" pos="0 0 0"/>
			<joint name="target_box_z" type="slide" axis="0 0 1" pos="0 0 0"/>
			<joint name="target_box_rx" type="hinge" axis="1 0 0" pos="0 0 0"/>
			<joint name="target_box_ry" type="hinge" axis="0 1 0" pos="0 0 0"/>
			<joint name="target_box_rz" type="hinge" axis="0 0 1" pos="0 0 0"/>
			<geom name="target_box_geom" type="box" size="0.025 0.025 0.025" rgba="1 0 0 1" mass="0.1" friction="2.0 0.5 0.01" solimp="0.95 0.99 0.01" solref="0.01 1" condim="6"/>
		</body>
	</worldbody>
    <keyframe>  
		<key name="front" time="0" qpos ="0 0 0 0 0 0 0 0 0 0 0 0 0 0 0 0 0 0"/>
    </keyframe>
</mujoco>